Report for assignment1.py start evaluation at <built-in method now of type object at 0x7fe53f435900>
Errors occurred during run at <built-in method now of type object at 0x7fe53f435900>!
b'multiprocessing.pool.RemoteTraceback: \n"""\nTraceback (most recent call last):\n  File "/commons/conda/lib/python3.8/multiprocessing/pool.py", line 125, in worker\n    result = (True, func(*args, **kwds))\n  File "/commons/conda/lib/python3.8/multiprocessing/pool.py", line 48, in mapstar\n    return list(map(*args))\n  File "assignment1.py", line 29, in ncbi_articles\n    with open(f\'{output_path}/{pmid}.xml\', \'wb\') as file:\nFileNotFoundError: [Errno 2] No such file or directory: \'/homes/martijntest/courses/programming3/2022/Shahadat_Hossain/Programming-3/Assignment1/output/8944180.xml\'\n"""\n\nThe above exception was the direct cause of the following exception:\n\nTraceback (most recent call last):\n  File "assignment1.py", line 46, in <module>\n    results = pool.map(ncbi_articles, references[0:10])\n  File "/commons/conda/lib/python3.8/multiprocessing/pool.py", line 364, in map\n    return self._map_async(func, iterable, mapstar, chunksize).get()\n  File "/commons/conda/lib/python3.8/multiprocessing/pool.py", line 771, in get\n    raise self._value\nFileNotFoundError: [Errno 2] No such file or directory: \'/homes/martijntest/courses/programming3/2022/Shahadat_Hossain/Programming-3/Assignment1/output/8944180.xml\'\n'
*** ASSIGNMENT assignment1.py STATUS: FAILED ***
